Workbook

Sheet original_data
A1: Location | B1: Rating | C1: Comment | D1: Transaction Date and Time | E1: Transaction Value | F1: feedback_id
A2: Domain | B2: 5 | C2: Awesome, friendly staff, they all are smiling and makes you start your day off with a great attitude | D2: 19/10/2024 6:03:00 AM | E2: 19.5 | F2: 4974583
A3: Timaru | B3: 5 | C3: The service | D3: 19/10/2024 6:09:00 AM | E3: 19.17 | F3: 4974584
A4: Upper Hutt | B4: 5 | C4: The staff are fabulous and neither is too much trouble. Also the coffee and food are good, the premises are war, well lite, clean and comfortable. A good venue all round. | D4: 19/10/2024 6:13:00 AM | E4: 10.6 | F4: 4974586
A5: Wellington central | B5: 4 | C5: More dairy + gluten free food options. | D5: 19/10/2024 6:21:00 AM | E5: 4 | F5: 4974587
A6: Henderson | B6: 5 | C6: Friendly welcoming staff always smiling | D6: 19/10/2024 6:43:00 AM | E6: 5.5 | F6: 4974591
A7: Ruakura | B7: 5 | C7: The team | D7: 19/10/2024 6:55:00 AM | E7: 4.8 | F7: 4974595
A8: Rosebank Road | B8: 5 | C8: Amazing service. | D8: 19/10/2024 5:49:00 AM | E8: 10.6 | F8: 4974596
A9: Domain | B9: 5 | C9: Always clean with good selection of food. Fantastic coffee with friendly personal service. | D9: 19/10/2024 6:45:00 AM | E9: 10 | F9: 4974600
A10: Auckland Central | B10: 5 | C10: Exceptional customer service | D10: 19/10/2024 6:30:00 AM | E10: 4 | F10: 4974606
A11: Wellington central | B11: 5 | C11: Great service, always friendly! | D11: 19/10/2024 7:04:00 AM | E11: 10.9 | F11: 4974607
A12: Domain | B12: 5 | C12: They make the best coffee and always so friendly | D12: 19/10/2024 7:18:00 AM | E12: 5.3 | F12: 4974609
A13: Botany | B13: 5 | C13: The people and service at Botany Town Center is always the best. AAA+ | D13: 19/10/2024 7:29:00 AM | E13: 23.2 | F13: 4974613
... A357: Domain | B357: 5 | C357: Love the friendly staff who have a smile on their faces and kind words everyday. | D357: 20/10/2024 6:21:01 AM | E357: 18 | F357: 4975449
A358: MT Wellington | B358: 5 | C358: 5 | D358: 20/10/2024 6:41:00 AM | E358: 6 | F358: 4975450
A359: Domain | B359: 5 | C359: Service and taste of coffee | D359: 20/10/2024 6:34:00 AM | E359: 5 | F359: 4975453
A360: Rotorua | B360: 5 | C360: the staff friendly welcome and excellent service | D360: 19/10/2024 8:12:00 AM | E360: 24 | F360: 4975457
A361: Dunedin | B361: 5 | C361: The friendly staff who are 'always' polite and very helpful. They always know what we want and are quick when it comes to service. Nothing is a bother. We have the best Cafe staff here at M10 Mega Dunedin. Thank you to Leo, Belyn, Jarrod, Geoff, Raul, Jasmine the rest of the team :) | D361: 20/10/2024 6:58:00 AM | E361: 8.28 | F361: 4975459
A362: Wanganui | B362: 5 | C362: The friendly greeting the quick service and the yummy food | D362: 19/10/2024 10:39:00 AM | E362: 13 | F362: 4975461
A363: Richmond | B363: 5 | C363: Excellent service and great coffee | D363: 20/10/2024 7:28:00 AM | E363: 3.5 | F363: 4975466
A364: Albany | B364: 5 | C364: Service | D364: 20/10/2024 7:20:00 AM | E364: 10.2 | F364: 4975467
A365: Timaru | B365: 5 | C365: Staff and service | D365: 20/10/2024 6:56:00 AM | E365: 25.2 | F365: 4975468
A366: Auckland Central | B366: 5 | C366: Service was amazing! Good food too | D366: 20/10/2024 7:33:00 AM | E366: 0 | F366: 4975469
A367: Auckland Central | B367: 5 | C367: Great service! | D367: 20/10/2024 7:27:00 AM | E367: 11.8 | F367: 4975471
A368: Crofton Downs | B368: 5 | C368: Great customer service | D368: 20/10/2024 7:29:00 AM | E368: 5.2 | F368: 4975474
A369: Timaru | B369: 5 | C369: Service | D369: 20/10/2024 7:37:00 AM | E369: 13.8 | F369: 4975475
A370: Kapiti | B370: 5 | C370: The friendly service at the counter. The staff were genuinely helpful . coffee was good too | D370: 19/10/2024 10:33:00 AM | E370: 4.05 | F370: 4975478
... A510: Broadway | B510: 5 | C510: Great service,yum food, nice staff | D510: 20/10/2024 9:01:00 AM | E510: 0 | F510: 4975740
A511: Richmond | B511: 5 | C511: What wowed" us was ... the usual warm greeting from the staff | D511: WEB | E511: 20/10/2020 8:24:00 AM | F511: 16.1 | G511: DEPLHCF | H511: 4975742
A512: Upper Hutt | B512: 5 | C512: Extensive menu and very friendly staff. Always made to feel welcome ?? | D512: 20/10/2024 9:28:01 AM | E512: 8.5 | F512: 4975743
A513: Ruakura | B513: 5 | C513: Great friendly service. ?? | D513: 20/10/2024 9:21:00 AM | E513: 22.3 | F513: 4975746
A514: Pakuranga | B514: 5 | C514: service and scone to die for. | D514: 20/10/2024 9:36:01 AM | E514: 15.6 | F514: 4975749
A515: Te Awamutu | B515: 5 | C515: Lovely food & great service! | D515: 20/10/2024 11:09:00 AM | E515: 23.8 | F515: 4975750
A516: Glen Innes | B516: 5 | C516: We ALWAYS get a friendly welcome from the team at ABCs Ellerslie. Fantastic!! | D516: 20/10/2024 8:55:00 AM | E516: 10.1 | F516: 4975752
A517: Queen Street | B517: 4 | C517: Cheese scone wasn’t very nice - hot drink great though! | D517: 20/10/2024 10:56:01 AM | E517: 4.5 | F517: 4975753
A518: Te Rapa | B518: 5 | C518: As I'm a local the customer service team already know my order before I get to the service desk. :) Always A+ service | D518: 20/10/2024 11:15:00 AM | E518: 8.55 | F518: 4975755
A519: Ruakura | B519: 5 | C519: Friendly staff | D519: 20/10/2024 9:46:00 AM | E519: 11.8 | F519: 4975757
A520: Ellerslie | B520: 5 | C520: Goid seevice & grest coffee | D520: 20/10/2024 11:23:00 AM | E520: 10.1 | F520: 4975759
A521: Marlborough | B521: 5 | C521: The staff and owners are just amazing not to mention the world class coffee the make... | D521: 20/10/2024 8:50:00 AM | E521: 14.79 | F521: 4975761
A522: Pukekohe | B522: 4 | C522: Had to wait a while for my scone and they also bought out the wrong coffee initially | D522: 20/10/2024 9:15:00 AM | E522: 15.1 | F522: 4975763
...

Sheet edited_data
A1: Location | B1: Rating | C1: Comment | D1: transaction_date_and_time_helper | E1: Date and Time | F1: transaction_value_helper | G1: Transaction Value | H1: feedback_id
A2: London St | B2: 5 | C2: Yesterday at ABCs we had a flat white each in Victoria Street. Hamilton. I was most impressed and asked the chap serving us for extra hot coffees (which I always do anyway) When we were drinking the coffees I thought gee these are good and so hot, so I asked the young man ^Did you heat our cups with hot water and he replied | D2: =SUBSTITUTE(SUBSTITUTE(F2,"$",""),",","") -> 241020120707 | E2: =UPPER(TEXT(DATE(2000+LEFT(D2,2), MID(D2,3,2), MID(D2,5,2)) + TIME(MID(D2,7,2), MID(D2,9,2), MID(D2,11,2)), "dd/mm/yyyy h:mm:ss AM/PM")) -> 20/10/2024 12:07:07 PM | F2: 241020120707 | H2: MFFPYCF
A3: Botany | B3: 5 | C3: Friendly service | D3: 19/10/2024 1:06:00 PM | E3: 19/10/2024 1:06:00 PM | F3: 5.3 | G3: 5.3 | H3: 4975114 | K3: {=SUMPRODUCT((LEN(C2:C100)-LEN(SUBSTITUTE(LOWER(C2:C100),"The","")))/LEN("The"))} -> 0
A4: Invercargill | B4: 5 | C4: The service is lovely. The food tasty. It has a nice feel to go into and it is quiet. Parking is easy. All in all I recommend this cafe to all my friends. | D4: 19/10/2024 1:33:00 PM | E4: 19/10/2024 1:33:00 PM | F4: 9 | G4: 9 | H4: 4975603
A5: Henderson | B5: 5 | C5: Great Service | D5: 19/10/2024 1:35:00 PM | E5: 19/10/2024 1:35:00 PM | F5: 9.8 | G5: 9.8 | H5: 4975106
A6: Pakuranga | B6: 4 | C6: some cabinet food is a bit expensive but we enjoyed our coffee and date & orange scone very much. The barista is very helpful and friendly, the surrounding clean and pleasant.as always. | D6: 19/10/2024 1:57:00 PM | E6: 19/10/2024 1:57:00 PM | F6: 13.5 | G6: 13.5 | H6: 4975367 | K6: {=SUMPRODUCT((LEN(C2:C100)-LEN(SUBSTITUTE(LOWER(C2:C100),LOWER("quick"),"")))/LEN("quick"))} -> 3
A7: Rangiora | B7: 5 | C7: Friendly and prompt service and the date and orange scones were beautiful. | D7: 19/10/2024 10:00:00 AM | E7: 19/10/2024 10:00:00 AM | F7: 18.5 | G7: 18.5 | H7: 4975653
A8: Petone | B8: 5 | C8: Clean and great service | D8: 19/10/2024 10:04:00 AM | E8: 19/10/2024 10:04:00 AM | F8: 9.3 | G8: 9.3 | H8: 4974905
A9: Cambridge | B9: 5 | C9: GREAT staff. So friendly :) | D9: 19/10/2024 10:04:00 AM | E9: 19/10/2024 10:04:00 AM | F9: 8.7 | G9: 8.7 | H9: 4975002
A10: Gate Pa | B10: 5 | C10: Friendly staff and fantastic coffee made just the way I love it. My safe place!! | D10: 19/10/2024 10:04:00 AM | E10: 19/10/2024 10:04:00 AM | F10: 0 | G10: 0 | H10: 4975252
A11: Palmerston Nth | B11: 5 | C11: The service and the food is second to none | D11: 19/10/2024 10:05:00 AM | E11: 19/10/2024 10:05:00 AM | F11: 44.3 | G11: 44.3 | H11: 4975030
A12: Te Rapa | B12: 5 | C12: Lovely food. Friendly staff. Beautiful atmosphere looking out to the garden centre. | D12: 19/10/2024 10:08:00 AM | E12: 19/10/2024 10:08:00 AM | F12: 24.8 | G12: 24.8 | H12: 4975448
A13: Warkworth | B13: 5 | C13: The service and the food | D13: 19/10/2024 10:09:00 AM | E13: 19/10/2024 10:09:00 AM | F13: 21.4 | G13: 21.4 | H13: 4975013
A14: Palmerston Nth | B14: 5 | C14: Thoughtful extra service received | D14: 19/10/2024 10:09:00 AM | E14: 19/10/2024 10:09:00 AM | F14: 17.3 | G14: 17.3 | H14: 4975086
A15: Rangiora | B15: 5 | C15: Great food anf service | D15: 19/10/2024 10:09:00 AM | E15: 19/10/2024 10:09:00 AM | F15: 14.3 | G15: 14.3 | H15: 4974947
A16: Te Rapa | B16: 5 | C16: service | D16: 19/10/2024 10:10:00 AM | E16: 19/10/2024 10:10:00 AM | F16: 26.5 | G16: 26.5 | H16: 4975194
A17: Glenfield | B17: 5 | C17: Fabulous muffins and carrot cake, perfect coffees and very friendly staff . Who could want for more! | D17: 19/10/2024 10:10:00 AM | E17: 19/10/2024 10:10:00 AM | F17: 14.2 | G17: 14.2 | H17: 4974979
A18: New Lynn | B18: 5 | C18: High standard as usual, friendly efficient staff.Splendid coffee! | D18: 19/10/2024 10:10:00 AM | E18: 19/10/2024 10:10:00 AM | F18: 9.8 | G18: 9.8 | H18: 4974990
... A421: Palmerston Nth | B421: 4 | C421: Ordered 2 coffees 1 was really good but 1 was very weak | D421: 19/10/2024 9:57:00 AM | E421: 19/10/2024 9:57:00 AM | F421: 0.8 | G421: 0.8 | H421: 4975309
A422: Richmond | B422: 5 | C422: What wowed" us was ... the usual warm greeting from the staff | D422: =SUBSTITUTE(SUBSTITUTE(F422,"$",""),",","") -> 44124.35 | E422: =UPPER(TEXT(D422, "dd/mm/yyyy h:mm:ss AM/PM")) -> 20/10/2020 8:24:00 AM | F422: 44124.35 | G422: 16.1
A423: Auckland Central | B423: 4 | C423: Hi, the coffee is always a good, hot temperature & consistent - so I rate it one of the best in Grafton. I adore the savoury scones with the cream cheese imbedded but, they all tend to run out swiftly! Maybe stock more? Also, I feel sometimes a bit sad for the plants making the plant wall" they tend to look thirsty quite often - Maybe a schedule to tend them? But | D423: =SUBSTITUTE(SUBSTITUTE(F423,"$",""),",","") -> 221020103413 | E423: =UPPER(TEXT(DATE(2000+LEFT(D423,2), MID(D423,3,2), MID(D423,5,2)) + TIME(MID(D423,7,2), MID(D423,9,2), MID(D423,11,2)), "dd/mm/yyyy h:mm:ss AM/PM")) -> 20/10/2022 10:34:13 AM | F423: 221020103413 | H423: WJZPJCF
A424: Oamaru | B424: 5 | C424: Friendly efficient staff,clean airy surroundings. Not rapt about the musak" when the waitress arrived with the order she asked if there was anything else we had ordered and hearing the reply in the negative took our numbered card away | D424: =SUBSTITUTE(SUBSTITUTE(F424,"$",""),",","") -> 221020122135 | E424: =UPPER(TEXT(DATE(2000+LEFT(D424,2), MID(D424,3,2), MID(D424,5,2)) + TIME(MID(D424,7,2), MID(D424,9,2), MID(D424,11,2)), "dd/mm/yyyy h:mm:ss AM/PM")) -> 20/10/2022 12:21:35 PM | F424: 221020122135 | H424: NFTUTGH
A425: Newtown | B425: 4 | C425: Have the kitchen" operating as couldnt get a toasted sandwich at 1.00pm on Friday. Lunchtime & at keast 2 staff there in the smaller Newtown cafe. Didnt make sense as could have a filled croissant from cabinet toasted | D425: =SUBSTITUTE(SUBSTITUTE(F425,"$",""),",","") -> 231020131234 | E425: =UPPER(TEXT(DATE(2000+LEFT(D425,2), MID(D425,3,2), MID(D425,5,2)) + TIME(MID(D425,7,2), MID(D425,9,2), MID(D425,11,2)), "dd/mm/yyyy h:mm:ss AM/PM")) -> 20/10/2023 1:12:34 PM | F425: 231020131234 | H425: MTKPDCF
A426: Westgate | B426: 5 | C426: Enjoyable food, friendly and efficient service and a very warm welcome. We are regular customers because of this. | D426: 20/10/2024 1:07:01 PM | E426: 20/10/2024 1:07:01 PM | F426: 25 | G426: 25 | H426: 4976280
A427: Bethlehem | B427: 5 | C427: Always love ABCs coffee. Our favorite cafe | D427: 20/10/2024 1:23:00 PM | E427: 20/10/2024 1:23:00 PM | F427: 5.8 | G427: 5.8 | H427: 4976223
A428: Botany | B428: 5 | C428: Orange and date scones,delicious,friendly service. | D428: 20/10/2024 1:28:00 PM | E428: 20/10/2024 1:28:00 PM | F428: 4.5 | G428: 4.5 | H428: 4976050
A429: Albany | B429: 4 | C429: The caramel slice was way too sweet. Coffee nice. Staff okay. Venue okay. | D429: 20/10/2024 1:30:00 PM | E429: 20/10/2024 1:30:00 PM | F429: 8.3 | G429: 8.3 | H429: 4976001
A430: Aubyn | B430: 5 | C430: Pleasant person counter | D430: 20/10/2024 1:39:00 PM | E430: 20/10/2024 1:39:00 PM | F430: 14.5 | G430: 14.5 | H430: 4976006
A431: Lincoln Road | B431: 4 | C431: More gluten free muffin options | D431: 20/10/2024 1:44:00 PM | E431: 20/10/2024 1:44:00 PM | F431: 10.4 | G431: 10.4 | H431: 4976091
A432: Manukau Centre | B432: 5 | C432: Service with a smo | D432: 20/10/2024 1:48:00 PM | E432: 20/10/2024 1:48:00 PM | F432: 58.2 | G432: 58.2 | H432: 4975979
A433: Newtown | B433: 4 | C433: Open longer | D433: 20/10/2024 1:53:00 PM | E433: 20/10/2024 1:53:00 PM | F433: 13.7 | G433: 13.7 | H433: 4975948
A434: Petone | B434: 5 | C434: Great food zbd good coffee | D434: 20/10/2024 10:00:00 AM | E434: 20/10/2024 10:00:00 AM | F434: 5 | G434: 5 | H434: 4976043
A435: Queenstown | B435: 5 | C435: Friendly staff great coffee and food. | D435: 20/10/2024 10:01:00 AM | E435: 20/10/2024 10:01:00 AM | F435: 4.77 | G435: 4.77 | H435: 4975629
A436: Whangarei | B436: 4 | C436: NOT 100% SURE AS IT WAS PRETTY GOOD | D436: 20/10/2024 10:02:00 AM | E436: 20/10/2024 10:02:00 AM | F436: 9.5 | G436: 9.5 | H436: 4976594
A437: Palmerston Nth | B437: 4 | C437: Coffee not as hot. It was at burn your tounge temp | D437: 20/10/2024 10:02:00 AM | E437: 20/10/2024 10:02:00 AM | F437: 9 | G437: 9 | H437: 4975697
... A603: Rosebank Road | B603: 5 | C603: Customer service | D603: 20/10/2024 6:39:00 AM | E603: 20/10/2024 6:39:00 AM | F603: 5.3 | G603: 5.3 | H603: 4975953
A604: MT Wellington | B604: 5 | C604: 5 | D604: 20/10/2024 6:41:00 AM | E604: 20/10/2024 6:41:00 AM | F604: 6 | G604: 6 | H604: 4975450
A605: Domain | B605: 4 | C605: Bb | D605: 20/10/2024 6:44:00 AM | E605: 20/10/2024 6:44:00 AM | F605: 9.3 | G605: 9.3 | H605: 4975485
A606: Sylvia Park | B606: 5 | C606: The always friendly staff. | D606: 20/10/2024 6:44:00 AM | E606: 20/10/2024 6:44:00 AM | F606: 2.85 | G606: 2.85 | H606: 4975690
A607: Williams Drive | B607: 5 | C607: Willingness to prepare my meal the way I want it and friendly staff. | D607: 20/10/2024 6:47:00 AM | E607: 20/10/2024 6:47:00 AM | F607: 23.7 | G607: 23.7 | H607: 4975912
...

Sheet word_count_in_comments
A1: Word/Phrase | B1: Appearances
A2: Atmosphere | B2: {=SUMPRODUCT((LEN(edited_data!$C$2:$C$2408)-LEN(SUBSTITUTE(LOWER(edited_data!$C$2:$C$2408),LOWER(A2),"")))/LEN("A3"))} -> 360
A3: Burger | B3: {=SUMPRODUCT((LEN(edited_data!$C$2:$C$2408)-LEN(SUBSTITUTE(LOWER(edited_data!$C$2:$C$2408),LOWER(A3),"")))/LEN("A3"))} -> 30
A4: Cheap | B4: {=SUMPRODUCT((LEN(edited_data!$C$2:$C$2408)-LEN(SUBSTITUTE(LOWER(edited_data!$C$2:$C$2408),LOWER(A4),"")))/LEN("A3"))} -> 15
A5: Chips | B5: {=SUMPRODUCT((LEN(edited_data!$C$2:$C$2408)-LEN(SUBSTITUTE(LOWER(edited_data!$C$2:$C$2408),LOWER(A5),"")))/LEN("A3"))} -> 15
A6: Clean | B6: {=SUMPRODUCT((LEN(edited_data!$C$2:$C$2408)-LEN(SUBSTITUTE(LOWER(edited_data!$C$2:$C$2408),LOWER(A6),"")))/LEN("A3"))} -> 242.5
A7: Cleanliness | B7: {=SUMPRODUCT((LEN(edited_data!$C$2:$C$2408)-LEN(SUBSTITUTE(LOWER(edited_data!$C$2:$C$2408),LOWER(A7),"")))/LEN("A3"))} -> 27.5
A8: Coffee | B8: {=SUMPRODUCT((LEN(edited_data!$C$2:$C$2408)-LEN(SUBSTITUTE(LOWER(edited_data!$C$2:$C$2408),LOWER(A8),"")))/LEN("A3"))} -> 2736
A9: Digusting | B9: {=SUMPRODUCT((LEN(edited_data!$C$2:$C$2408)-LEN(SUBSTITUTE(LOWER(edited_data!$C$2:$C$2408),LOWER(A9),"")))/LEN("A3"))} -> 0
A10: Drinks | B10: {=SUMPRODUCT((LEN(edited_data!$C$2:$C$2408)-LEN(SUBSTITUTE(LOWER(edited_data!$C$2:$C$2408),LOWER(A10),"")))/LEN("A3"))} -> 96
A11: Dry | B11: {=SUMPRODUCT((LEN(edited_data!$C$2:$C$2408)-LEN(SUBSTITUTE(LOWER(edited_data!$C$2:$C$2408),LOWER(A11),"")))/LEN("A3"))} -> 12
A12: Efficient | B12: {=SUMPRODUCT((LEN(edited_data!$C$2:$C$2408)-LEN(SUBSTITUTE(LOWER(edited_data!$C$2:$C$2408),LOWER(A12),"")))/LEN("A3"))} -> 351
A13: Excellent | B13: {=SUMPRODUCT((LEN(edited_data!$C$2:$C$2408)-LEN(SUBSTITUTE(LOWER(edited_data!$C$2:$C$2408),LOWER(A13),"")))/LEN("A3"))} -> 585
... A27: Queue | B27: {=SUMPRODUCT((LEN(edited_data!$C$2:$C$2408)-LEN(SUBSTITUTE(LOWER(edited_data!$C$2:$C$2408),LOWER(A27),"")))/LEN("A3"))} -> 5
A28: Quick | B28: {=SUMPRODUCT((LEN(edited_data!$C$2:$C$2408)-LEN(SUBSTITUTE(LOWER(edited_data!$C$2:$C$2408),LOWER(A28),"")))/LEN(A28))} -> 105
A29: Server | B29: {=SUMPRODUCT((LEN(edited_data!$C$2:$C$2408)-LEN(SUBSTITUTE(LOWER(edited_data!$C$2:$C$2408),LOWER(A29),"")))/LEN("A3"))} -> 18
A30: Service | B30: {=SUMPRODUCT((LEN(edited_data!$C$2:$C$2408)-LEN(SUBSTITUTE(LOWER(edited_data!$C$2:$C$2408),LOWER(A30),"")))/LEN("A3"))} -> 3566.5
A31: Slow | B31: {=SUMPRODUCT((LEN(edited_data!$C$2:$C$2408)-LEN(SUBSTITUTE(LOWER(edited_data!$C$2:$C$2408),LOWER(A31),"")))/LEN("A3"))} -> 20
A32: Staff | B32: {=SUMPRODUCT((LEN(edited_data!$C$2:$C$2408)-LEN(SUBSTITUTE(LOWER(edited_data!$C$2:$C$2408),LOWER(A32),"")))/LEN("A3"))} -> 1957.5
A33: Tasty | B33: {=SUMPRODUCT((LEN(edited_data!$C$2:$C$2408)-LEN(SUBSTITUTE(LOWER(edited_data!$C$2:$C$2408),LOWER(A33),"")))/LEN("A3"))} -> 82.5
A34: Tidy | B34: {=SUMPRODUCT((LEN(edited_data!$C$2:$C$2408)-LEN(SUBSTITUTE(LOWER(edited_data!$C$2:$C$2408),LOWER(A34),"")))/LEN("A3"))} -> 24
A35: Wait | B35: {=SUMPRODUCT((LEN(edited_data!$C$2:$C$2408)-LEN(SUBSTITUTE(LOWER(edited_data!$C$2:$C$2408),LOWER(A35),"")))/LEN("A3"))} -> 68
A36: Wonderful | B36: {=SUMPRODUCT((LEN(edited_data!$C$2:$C$2408)-LEN(SUBSTITUTE(LOWER(edited_data!$C$2:$C$2408),LOWER(A36),"")))/LEN("A3"))} -> 135
A37: Yummy | B37: {=SUMPRODUCT((LEN(edited_data!$C$2:$C$2408)-LEN(SUBSTITUTE(LOWER(edited_data!$C$2:$C$2408),LOWER(A37),"")))/LEN("A3"))} -> 120

Sheet problem_log
A1: Issue | B1: Location | C1: Magnitude | D1: Resolved | E1: Technique (If Resolved)
A2: Transaction Date stored in transcation value | B2: Multiple cells | C2: 0.0016 | D2: Yes | E2: Created new column called cleaned_date_and_time to get correct and move transcation values to appropriate column
E3: Date deleted in transactions column and replaced with actual transcation value if it exists (there was only one).
A5: Data stored in columns not stored as correct types in columns | B5: Most columns | D5: Yes | E5: Convert to correct data type
A7: Miscellaneous feedback IDs appearing outside the table | B7: Columns I & J (edited_data) sheet | C7: 0.0024 | D7: Yes | E7: Deleted as it's not needed for analysis
